Workbook
Name Slicer_Product_Category: #N/A
Name Slicer_Product_Category1: #N/A

Sheet Customer_Dim
A1: Customer_ID_Inconsistency | B1: Name Inconsistency after Proper & Trim | C1: Age | D1: Gender | E1: City_Inconsistency | F1: State | G1: Country_Inconsistency | H1: Loyalty_Level_Imputation
A2: CUST1000 | B2: Sheena Bonilla | C2: 55 | D2: Male | E2: Donaldton | F2: North Carolina | G2: USA | H2: Unknown
A3: CUST1001 | B3: Eugene Nelson | C3: 26 | D3: Female | E3: Phillipsmouth | F3: North Dakota | G3: USA | H3: Platinum
A4: CUST1002 | B4: Dr. Benjamin Price | C4: 29 | D4: Female | E4: Kylebury | F4: Alabama | G4: USA | H4: Platinum
A5: CUST1003 | B5: Jeremy Harris | C5: 59 | D5: Female | E5: Thomastown | F5: Ohio | G5: USA | H5: Bronze
A6: CUST1004 | B6: Caroline Collins | C6: 64 | D6: Female | E6: Nicholasshire | F6: California | G6: USA | H6: Silver
A7: CUST1005 | B7: Christine Vaughn | C7: 24 | D7: Male | E7: East Amandamouth | F7: Oregon | G7: USA | H7: Bronze
A8: CUST1006 | B8: Amber Jackson | C8: 29 | D8: Female | E8: Deborahborough | F8: South Dakota | G8: USA | H8: Platinum
A9: CUST1007 | B9: Daniel Boyd | C9: 29 | D9: Female | E9: West Pamelafurt | F9: West Virginia | G9: USA | H9: Bronze
A10: CUST1008 | B10: Melissa Howard | C10: 53 | D10: Female | E10: Maynardton | F10: New Hampshire | G10: USA | H10: Gold
A11: CUST1009 | B11: Ms. Maria Leach | C11: 64 | D11: Male | E11: Melissashire | F11: Pennsylvania | G11: USA | H11: Platinum
A12: CUST1010 | B12: Dominic Page | C12: 53 | D12: Male | E12: Port Michaelburgh | F12: Pennsylvania | G12: USA | H12: Bronze
A13: CUST1011 | B13: Brian Lopez | C13: 28 | D13: Female | E13: East Krista | F13: New York | G13: USA | H13: Gold
... A501: CUST1499 | B501: Philip Pennington | C501: 27 | D501: Female | E501: East Valerieview | F501: Oregon | G501: USA | H501: Platinum

Sheet Product_Dim
A1: Product_ID | B1: Product_Name | C1: Category | D1: Sub_Category | E1: Brand | F1: Cost Imputation | G1: Stock Imputation
A2: PROD0 | B2: Brother Laser Printer | C2: Electronics | D2: Computer | E2: Hunt Inc | F2: 112.42 | G2: 416
A3: PROD1 | B3: Men's Graphic T-Shirt | C3: Clothing | D3: Tops | E3: Terry-Moore | F3: 342.56 | G3: 181
A4: PROD2 | B4: Women's Casual Hoodie | C4: Clothing | D4: Outerwear | E4: Sims Inc | F4: 254.04362 | G4: 352
A5: PROD3 | B5: Men's Running Jacket | C5: Clothing | D5: Outerwear | E5: Pineda Ltd | F5: 364.67 | G5: 452
A6: PROD4 | B6: Women's Yoga Pants | C6: Clothing | D6: Bottoms | E6: Gonzales-Davis | F6: 306.46 | G6: 487
A7: PROD5 | B7: Men's Leather Belt | C7: Clothing | D7: Accessories | E7: Baldwin, Garza and Gonzalez | F7: 261 | G7: 59
A8: PROD6 | B8: Herbal Face Moisturizer | C8: Beauty | D8: Skincare | E8: Davidson PLC | F8: 312.8 | G8: 350
A9: PROD7 | B9: LED Table Lamp | C9: Home | D9: Lighting | E9: Harrell LLC | F9: 218.86 | G9: 170
A10: PROD8 | B10: Wireless Bluetooth Earbuds | C10: Electronics | D10: Audio | E10: Perez-Johnston | F10: 439.07 | G10: 142
A11: PROD9 | B11: Adjustable Dumbbell Set | C11: Sports | D11: Fitness | E11: Hill PLC | F11: 495.72 | G11: 323
A12: PROD10 | B12: Ceramic Kitchen Bowl Set | C12: Home | D12: Kitchen | E12: Hamilton Group | F12: 298.86 | G12: 308
A13: PROD11 | B13: HD Smart TV Stick | C13: Electronics | D13: Accessories | E13: Gibson, Hobbs and Weaver | F13: 449.4 | G13: 273.49485
... A101: PROD99 | B101: Stainless Steel Cookware Set | C101: Home | D101: Kitchen | E101: Campbell Ltd | F101: 201.41 | G101: 146

Sheet Store_Dim
A1: Store_ID | B1: Store_Name | C1: Region | D1: City | E1: Store_Type
A2: STORE0 | B2: Rivera-Warner | C2: East | D2: Washingtonfurt | E2: Flagship
A3: STORE1 | B3: Martinez, Adkins and Johnson | C3: North | D3: Danielmouth | E3: Flagship
A4: STORE2 | B4: Black-Horn | C4: South | D4: North Nancyview | E4: Outlet
A5: STORE3 | B5: Johnson-Wright | C5: North | D5: Hoodberg | E5: Outlet
A6: STORE4 | B6: Alexander Group | C6: South | D6: Port Sharon | E6: Online
A7: STORE5 | B7: Gray Ltd | C7: North | D7: New Michaelchester | E7: Outlet
A8: STORE6 | B8: Benson-Elliott | C8: East | D8: Port Josephberg | E8: Online
A9: STORE7 | B9: Martinez-Mullins | C9: South | D9: Williamsfurt | E9: Online
A10: STORE8 | B10: Bean, Jones and Park | C10: West | D10: Thompsonborough | E10: Online
A11: STORE9 | B11: Moore, Padilla and Butler | C11: South | D11: East Johnstad | E11: Flagship
A12: STORE10 | B12: Hill, Wagner and Ballard | C12: East | D12: East Davidville | E12: Online
... A21: STORE19 | B21: Mann-Austin | C21: East | D21: Vasquezborough | E21: Online

Sheet Sales_Fact
A1: Sales_ID | B1: Order_Date | C1: Order_Month | D1: Order_Year | E1: Customer_ID | F1: Gender | G1: Age | H1: Product_ID | I1: Product_Name | J1: Product Category | K1: Product_SubCategory | L1: Store_ID | M1: Store_Name | N1: Store_Region | O1: Store_city | P1: Store_Type | Q1: Payment_Type | R1: Quantity | S1: Discount | T1: Unit_Price | U1: Total_Amount
A2: SALE0 | B2: 45480 | C2: 7 | D2: 2024 | E2: CUST1409 | F2: =VLOOKUP(E2,Customer_Dim!A:F,4,TRUE) -> Male | G2: =VLOOKUP(E2,Customer_Dim!A:F,3,TRUE) -> 55 | H2: PROD97 | I2: =VLOOKUP(H2,Product_Dim!A:C,2,TRUE) -> Cricket Bat | J2: =VLOOKUP(H2,Product_Dim!A:C,3,TRUE) -> Sports | K2: =VLOOKUP(H2,Product_Dim!A:D,4,TRUE) -> Team Sports | L2: STORE3 | M2: =VLOOKUP(L2,Store_Dim!A:E,2,TRUE) -> Mann-Austin | N2: =VLOOKUP(L2,Store_Dim!A:E,3,TRUE) -> East | O2: =VLOOKUP(L2,Store_Dim!A:E,4,TRUE) -> Vasquezborough | P2: =VLOOKUP(L2,Store_Dim!A:E,5,TRUE) -> Online | Q2: Credit Card | R2: 1 | S2: 0.09 | T2: =U2/ (R2 * (1 - S2)) -> 218.04 | U2: 198.4164
A3: SALE1 | B3: 45285 | C3: 12 | D3: 2023 | E3: CUST1467 | F3: =VLOOKUP(E3,Customer_Dim!A:F,4,TRUE) -> Female | G3: =VLOOKUP(E3,Customer_Dim!A:F,3,TRUE) -> 63 | H3: PROD74 | I3: =VLOOKUP(H3,Product_Dim!A:C,2,TRUE) -> Bluetooth Car Audio System | J3: =VLOOKUP(H3,Product_Dim!A:C,3,TRUE) -> Electronics | K3: =VLOOKUP(H3,Product_Dim!A:D,4,TRUE) -> Audio | L3: STORE17 | M3: =VLOOKUP(L3,Store_Dim!A:E,2,TRUE) -> Holloway Ltd | N3: =VLOOKUP(L3,Store_Dim!A:E,3,TRUE) -> North | O3: =VLOOKUP(L3,Store_Dim!A:E,4,TRUE) -> Bensonhaven | P3: =VLOOKUP(L3,Store_Dim!A:E,5,TRUE) -> Flagship | Q3: PayPal | R3: 3 | S3: 0.27 | T3: =U3/ (R3 * (1 - S3)) -> 104.47 | U3: 228.7893
A4: SALE2 | B4: 45446 | C4: 6 | D4: 2024 | E4: CUST1056 | F4: =VLOOKUP(E4,Customer_Dim!A:F,4,TRUE) -> Female | G4: =VLOOKUP(E4,Customer_Dim!A:F,3,TRUE) -> 49 | H4: PROD49 | I4: =VLOOKUP(H4,Product_Dim!A:C,2,TRUE) -> Men's Roll-On Perfume | J4: =VLOOKUP(H4,Product_Dim!A:C,3,TRUE) -> Beauty | K4: =VLOOKUP(H4,Product_Dim!A:D,4,TRUE) -> Fragrance | L4: STORE8 | M4: =VLOOKUP(L4,Store_Dim!A:E,2,TRUE) -> Mann-Austin | N4: =VLOOKUP(L4,Store_Dim!A:E,3,TRUE) -> East | O4: =VLOOKUP(L4,Store_Dim!A:E,4,TRUE) -> Vasquezborough | P4: =VLOOKUP(L4,Store_Dim!A:E,5,TRUE) -> Online | Q4: Credit Card | R4: 4 | S4: 0.25 | T4: =U4/ (R4 * (1 - S4)) -> 914.05 | U4: 2742.15
A5: SALE3 | B5: 45259 | C5: 11 | D5: 2023 | E5: CUST1346 | F5: =VLOOKUP(E5,Customer_Dim!A:F,4,TRUE) -> Female | G5: =VLOOKUP(E5,Customer_Dim!A:F,3,TRUE) -> 58 | H5: PROD76 | I5: =VLOOKUP(H5,Product_Dim!A:C,2,TRUE) -> Wireless Mouse | J5: =VLOOKUP(H5,Product_Dim!A:C,3,TRUE) -> Electronics | K5: =VLOOKUP(H5,Product_Dim!A:D,4,TRUE) -> Computer | L5: STORE8 | M5: =VLOOKUP(L5,Store_Dim!A:E,2,TRUE) -> Mann-Austin | N5: =VLOOKUP(L5,Store_Dim!A:E,3,TRUE) -> East | O5: =VLOOKUP(L5,Store_Dim!A:E,4,TRUE) -> Vasquezborough | P5: =VLOOKUP(L5,Store_Dim!A:E,5,TRUE) -> Online | Q5: COD | R5: 1 | S5: 0.16 | T5: =U5/ (R5 * (1 - S5)) -> 921.51 | U5: 774.0684
A6: SALE4 | B6: 45297 | C6: 1 | D6: 2024 | E6: CUST1493 | F6: =VLOOKUP(E6,Customer_Dim!A:F,4,TRUE) -> Male | G6: =VLOOKUP(E6,Customer_Dim!A:F,3,TRUE) -> 28 | H6: PROD59 | I6: =VLOOKUP(H6,Product_Dim!A:C,2,TRUE) -> Men's Hair Styling Gel | J6: =VLOOKUP(H6,Product_Dim!A:C,3,TRUE) -> Beauty | K6: =VLOOKUP(H6,Product_Dim!A:D,4,TRUE) -> Haircare | L6: STORE5 | M6: =VLOOKUP(L6,Store_Dim!A:E,2,TRUE) -> Mann-Austin | N6: =VLOOKUP(L6,Store_Dim!A:E,3,TRUE) -> East | O6: =VLOOKUP(L6,Store_Dim!A:E,4,TRUE) -> Vasquezborough | P6: =VLOOKUP(L6,Store_Dim!A:E,5,TRUE) -> Online | Q6: Credit Card | R6: 3 | S6: 0.18 | T6: =U6/ (R6 * (1 - S6)) -> 745.3 | U6: 1833.438
A7: SALE5 | B7: 45499 | C7: 7 | D7: 2024 | E7: CUST1116 | F7: =VLOOKUP(E7,Customer_Dim!A:F,4,TRUE) -> Female | G7: =VLOOKUP(E7,Customer_Dim!A:F,3,TRUE) -> 18 | H7: PROD15 | I7: =VLOOKUP(H7,Product_Dim!A:C,2,TRUE) -> 4K Home Projector | J7: =VLOOKUP(H7,Product_Dim!A:C,3,TRUE) -> Electronics | K7: =VLOOKUP(H7,Product_Dim!A:D,4,TRUE) -> Appliances | L7: STORE7 | M7: =VLOOKUP(L7,Store_Dim!A:E,2,TRUE) -> Mann-Austin | N7: =VLOOKUP(L7,Store_Dim!A:E,3,TRUE) -> East | O7: =VLOOKUP(L7,Store_Dim!A:E,4,TRUE) -> Vasquezborough | P7: =VLOOKUP(L7,Store_Dim!A:E,5,TRUE) -> Online | Q7: COD | R7: 3 | S7: 0.19 | T7: =U7/ (R7 * (1 - S7)) -> 147.01 | U7: 357.2343
A8: SALE6 | B8: 45850 | C8: 7 | D8: 2025 | E8: CUST1016 | F8: =VLOOKUP(E8,Customer_Dim!A:F,4,TRUE) -> Female | G8: =VLOOKUP(E8,Customer_Dim!A:F,3,TRUE) -> 24 | H8: PROD56 | I8: =VLOOKUP(H8,Product_Dim!A:C,2,TRUE) -> Premium Blanket Throw | J8: =VLOOKUP(H8,Product_Dim!A:C,3,TRUE) -> Home | K8: =VLOOKUP(H8,Product_Dim!A:D,4,TRUE) -> Decor | L8: STORE4 | M8: =VLOOKUP(L8,Store_Dim!A:E,2,TRUE) -> Mann-Austin | N8: =VLOOKUP(L8,Store_Dim!A:E,3,TRUE) -> East | O8: =VLOOKUP(L8,Store_Dim!A:E,4,TRUE) -> Vasquezborough | P8: =VLOOKUP(L8,Store_Dim!A:E,5,TRUE) -> Online | Q8: PayPal | R8: 2 | S8: 0.15 | T8: =U8/ (R8 * (1 - S8)) -> 785.31 | U8: 1335.027
A9: SALE7 | B9: 45248 | C9: 11 | D9: 2023 | E9: CUST1152 | F9: =VLOOKUP(E9,Customer_Dim!A:F,4,TRUE) -> Female | G9: =VLOOKUP(E9,Customer_Dim!A:F,3,TRUE) -> 41 | H9: PROD70 | I9: =VLOOKUP(H9,Product_Dim!A:C,2,TRUE) -> Kitchen Storage Rack | J9: =VLOOKUP(H9,Product_Dim!A:C,3,TRUE) -> Home | K9: =VLOOKUP(H9,Product_Dim!A:D,4,TRUE) -> Storage | L9: STORE8 | M9: =VLOOKUP(L9,Store_Dim!A:E,2,TRUE) -> Mann-Austin | N9: =VLOOKUP(L9,Store_Dim!A:E,3,TRUE) -> East | O9: =VLOOKUP(L9,Store_Dim!A:E,4,TRUE) -> Vasquezborough | P9: =VLOOKUP(L9,Store_Dim!A:E,5,TRUE) -> Online | Q9: PayPal | R9: 4 | S9: 0.23 | T9: =U9/ (R9 * (1 - S9)) -> 342.39 | U9: 1054.5612
A10: SALE8 | B10: 45781 | C10: 5 | D10: 2025 | E10: CUST1187 | F10: =VLOOKUP(E10,Customer_Dim!A:F,4,TRUE) -> Female | G10: =VLOOKUP(E10,Customer_Dim!A:F,3,TRUE) -> 60 | H10: PROD99 | I10: =VLOOKUP(H10,Product_Dim!A:C,2,TRUE) -> Stainless Steel Cookware Set | J10: =VLOOKUP(H10,Product_Dim!A:C,3,TRUE) -> Home | K10: =VLOOKUP(H10,Product_Dim!A:D,4,TRUE) -> Kitchen | L10: STORE5 | M10: =VLOOKUP(L10,Store_Dim!A:E,2,TRUE) -> Mann-Austin | N10: =VLOOKUP(L10,Store_Dim!A:E,3,TRUE) -> East | O10: =VLOOKUP(L10,Store_Dim!A:E,4,TRUE) -> Vasquezborough | P10: =VLOOKUP(L10,Store_Dim!A:E,5,TRUE) -> Online | Q10: PayPal | R10: 3 | S10: 0.07 | T10: =U10/ (R10 * (1 - S10)) -> 448.25 | U10: 1250.6175
A11: SALE9 | B11: 45869 | C11: 7 | D11: 2025 | E11: CUST1464 | F11: =VLOOKUP(E11,Customer_Dim!A:F,4,TRUE) -> Female | G11: =VLOOKUP(E11,Customer_Dim!A:F,3,TRUE) -> 45 | H11: PROD33 | I11: =VLOOKUP(H11,Product_Dim!A:C,2,TRUE) -> Modern Wall Clock | J11: =VLOOKUP(H11,Product_Dim!A:C,3,TRUE) -> Home | K11: =VLOOKUP(H11,Product_Dim!A:D,4,TRUE) -> Decor | L11: STORE0 | M11: =VLOOKUP(L11,Store_Dim!A:E,2,TRUE) -> Rivera-Warner | N11: =VLOOKUP(L11,Store_Dim!A:E,3,TRUE) -> East | O11: =VLOOKUP(L11,Store_Dim!A:E,4,TRUE) -> Washingtonfurt | P11: =VLOOKUP(L11,Store_Dim!A:E,5,TRUE) -> Flagship | Q11: PayPal | R11: 2 | S11: 0.23 | T11: =U11/ (R11 * (1 - S11)) -> 873.17 | U11: 1344.6818
A12: SALE10 | B12: 45335 | C12: 2 | D12: 2024 | E12: CUST1065 | F12: =VLOOKUP(E12,Customer_Dim!A:F,4,TRUE) -> Female | G12: =VLOOKUP(E12,Customer_Dim!A:F,3,TRUE) -> 21 | H12: PROD24 | I12: =VLOOKUP(H12,Product_Dim!A:C,2,TRUE) -> Foldable Camping Chair | J12: =VLOOKUP(H12,Product_Dim!A:C,3,TRUE) -> Sports | K12: =VLOOKUP(H12,Product_Dim!A:D,4,TRUE) -> Outdoor | L12: STORE14 | M12: =VLOOKUP(L12,Store_Dim!A:E,2,TRUE) -> Mcdonald Inc | N12: =VLOOKUP(L12,Store_Dim!A:E,3,TRUE) -> South | O12: =VLOOKUP(L12,Store_Dim!A:E,4,TRUE) -> Christopherland | P12: =VLOOKUP(L12,Store_Dim!A:E,5,TRUE) -> Outlet | Q12: Credit Card | R12: 1 | S12: 0.07 | T12: =U12/ (R12 * (1 - S12)) -> 278.63 | U12: 259.1259
A13: SALE11 | B13: 45801 | C13: 5 | D13: 2025 | E13: CUST1320 | F13: =VLOOKUP(E13,Customer_Dim!A:F,4,TRUE) -> Female | G13: =VLOOKUP(E13,Customer_Dim!A:F,3,TRUE) -> 34 | H13: PROD39 | I13: =VLOOKUP(H13,Product_Dim!A:C,2,TRUE) -> Portable Power Bank | J13: =VLOOKUP(H13,Product_Dim!A:C,3,TRUE) -> Electronics | K13: =VLOOKUP(H13,Product_Dim!A:D,4,TRUE) -> Mobile | L13: STORE1 | M13: =VLOOKUP(L13,Store_Dim!A:E,2,TRUE) -> Martinez, Adkins and Johnson | N13: =VLOOKUP(L13,Store_Dim!A:E,3,TRUE) -> North | O13: =VLOOKUP(L13,Store_Dim!A:E,4,TRUE) -> Danielmouth | P13: =VLOOKUP(L13,Store_Dim!A:E,5,TRUE) -> Flagship | Q13: Credit Card | R13: 4 | S13: 0.17 | T13: =U13/ (R13 * (1 - S13)) -> 286.92 | U13: 952.5744
... A2001: SALE1999 | B2001: 45267 | C2001: 12 | D2001: 2023 | E2001: CUST1023 | F2001: =VLOOKUP(E2001,Customer_Dim!A:F,4,TRUE) -> Female | G2001: =VLOOKUP(E2001,Customer_Dim!A:F,3,TRUE) -> 52 | H2001: PROD76 | I2001: =VLOOKUP(H2001,Product_Dim!A:C,2,TRUE) -> Wireless Mouse | J2001: =VLOOKUP(H2001,Product_Dim!A:C,3,TRUE) -> Electronics | K2001: =VLOOKUP(H2001,Product_Dim!A:D,4,TRUE) -> Computer | L2001: STORE19 | M2001: =VLOOKUP(L2001,Store_Dim!A:E,2,TRUE) -> Mann-Austin | N2001: =VLOOKUP(L2001,Store_Dim!A:E,3,TRUE) -> East | O2001: =VLOOKUP(L2001,Store_Dim!A:E,4,TRUE) -> Vasquezborough | P2001: =VLOOKUP(L2001,Store_Dim!A:E,5,TRUE) -> Online | Q2001: PayPal | R2001: 3 | S2001: 0.17 | T2001: =U2001/ (R2001 * (1 - S2001)) -> 68.45 | U2001: 170.4405

Sheet Data Analysis
A1: Column1 | B1: Column2 | C1: Column3 | D1: Column4
A2: Unit_Price_Imputation | C2: Total_Amount_Impute
A4: Mean | B4: 512.61946 | C4: Mean | D4: 1085.4537
A5: Standard Error | B5: 6.3293719 | C5: Standard Error | D5: 18.352421
A6: Median | B6: 521.805 | C6: Median | D6: 867.424
A7: Mode | B7: 0 | C7: Mode | D7: 0
A8: Standard Deviation | B8: 283.05812 | C8: Standard Deviation | D8: 820.74521
A9: Sample Variance | B9: 80121.897 | C9: Sample Variance | D9: 673622.71
A10: Kurtosis | B10: -1.1928513 | C10: Kurtosis | D10: 0.04202509
A11: Skewness | B11: -0.035404674 | C11: Skewness | D11: 0.87779579
A12: Range | B12: 999.89 | C12: Range | D12: 3908.2428
A13: Minimum | B13: 0 | C13: Minimum | D13: 0
A14: Maximum | B14: 999.89 | C14: Maximum | D14: 3908.2428
A15: Sum | B15: 1025238.9 | C15: Sum | D15: 2170907.5
A16: Count | B16: 2000 | C16: Count | D16: 2000
B17: 1 | D17: 3

Sheet Pivot
A1: Total Amount - Month Analysis
A3: Sum of Total_Amount_Impute | B3: Column Labels
A4: Row Labels | B4: 2023 | C4: 2024 | D4: 2025 | E4: Grand Total
A5: Jan | C5: 17475.781 | D5: 31068.477 | E5: 48544.258
A6: Feb | C6: 10390.098 | D6: 20714.424 | E6: 31104.522
A7: Mar | C7: 10210.378 | D7: 27318.789 | E7: 37529.167
A8: Apr | C8: 14089.935 | D8: 26119.607 | E8: 40209.542
A9: May | C9: 11179.191 | D9: 28701.484 | E9: 39880.675
A10: Jun | C10: 16612.86 | D10: 23737.026 | E10: 40349.886
A11: Jul | C11: 22672.498 | D11: 14991.061 | E11: 37663.558
A12: Aug | C12: 17901.438 | D12: 18040.742 | E12: 35942.181
A13: Sep | C13: 14111.645 | D13: 21867.681 | E13: 35979.326
A14: Oct | B14: 9679.2647 | C14: 22322.505 | D14: 8421.9132 | E14: 40423.683
A15: Nov | B15: 23225.545 | C15: 12501.153 | E15: 35726.698
A16: Dec | B16: 12883.448 | C16: 20583.228 | E16: 33466.675
A17: Grand Total | B17: 45788.257 | C17: 190050.71 | D17: 220981.2 | E17: 456820.17
A20: Sum of Total_Amount | B20: Column Labels
A21: Row Labels | B21: Sports
A22: Female | B22: 327229.31
A23: Male | B23: 216365.94
A33: Payment type vs Sales
A35: Row Labels | B35: Count of Sales_ID
A36: COD | B36: 660
A37: Credit Card | B37: 645
A38: PayPal | B38: 695
A39: Grand Total | B39: 2000
A47: Top 10 Product sales
A49: Row Labels | B49: Sum of Total_Amount
A50: Accessories | B50: 136318.96
A51: Equipment | B51: 105855.65
A52: Fitness | B52: 128756.07
A53: Outdoor | B53: 48645.913
A54: Team Sports | B54: 124018.66
A61: Store Region vs Total sales
A63: Row Labels | B63: Sum of Total_Amount
A64: East | B64: 1198128.1
A65: North | B65: 754826.12
A66: South | B66: 106248.28
A67: West | B67: 111704.94
A68: Grand Total | B68: 2170907.5
...

Sheet Dashboard
A1: E-Commerce Sales Analysis Dashboard Report
